<Type Name="TargetInvocationException" FullName="System.Reflection.TargetInvocationException">
  <TypeSignature Language="C#" Value="public sealed class TargetInvocationException : ApplicationException" />
  <TypeSignature Language="ILAsm" Value=".class public auto ansi serializable sealed beforefieldinit TargetInvocationException extends System.ApplicationException" />
  <AssemblyInfo>
    <AssemblyName>mscorlib</AssemblyName>
    <AssemblyVersion>1.0.5000.0</AssemblyVersion>
    <AssemblyVersion>2.0.0.0</AssemblyVersion>
    <AssemblyVersion>4.0.0.0</AssemblyVersion>
  </AssemblyInfo>
  <Base>
    <BaseTypeName>System.ApplicationException</BaseTypeName>
  </Base>
  <Interfaces />
  <Attributes>
    <Attribute>
      <AttributeName>System.Runtime.InteropServices.ComVisible(true)</AttributeName>
    </Attribute>
  </Attributes>
  <Docs>
    <summary>The exception that is thrown by methods invoked through reflection. This class cannot be inherited.</summary>
    <remarks>
      <format type="text/markdown"><![CDATA[  
  
## Remarks  
 For more information, see <xref:System.Reflection.MethodBase.Invoke%2A>.  
  
 `TargetInvocationException` uses the HRESULT COR_E_TARGETINVOCATION which has the value 0x80131604.  
  
 When created, the `TargetInvocationException` is passed a reference to the exception thrown by the method invoked through reflection. The <xref:System.Exception.InnerException%2A> property holds the underlying exception.  
  
 ]]></format>
    </remarks>
    <threadsafe />
  </Docs>
  <Members>
    <Member MemberName=".ctor">
      <MemberSignature Language="C#" Value="public TargetInvocationException (Exception inner);" />
      <MemberSignature Language="ILAsm" Value=".method public hidebysig specialname rtspecialname instance void .ctor(class System.Exception inner) cil managed" />
      <MemberType>Constructor</MemberType>
      <AssemblyInfo>
        <AssemblyName>mscorlib</AssemblyName>
        <AssemblyVersion>1.0.5000.0</AssemblyVersion>
        <AssemblyVersion>2.0.0.0</AssemblyVersion>
        <AssemblyVersion>4.0.0.0</AssemblyVersion>
      </AssemblyInfo>
      <Parameters>
        <Parameter Name="inner" Type="System.Exception" />
      </Parameters>
      <Docs>
        <param name="inner">The exception that is the cause of the current exception. If the `inner` parameter is not <see langword="null" />, the current exception is raised in a <see langword="catch" /> block that handles the inner exception.</param>
        <summary>Initializes a new instance of the <see cref="T:System.Reflection.TargetInvocationException" /> class with a reference to the inner exception that is the cause of this exception.</summary>
        <remarks>
          <format type="text/markdown"><![CDATA[  
  
## Remarks  
 An exception that is thrown as a direct result of a previous exception should include a reference to the previous exception in the <xref:System.Exception.InnerException%2A> property. The <xref:System.Exception.InnerException%2A> property returns the same value that is passed into the constructor, or `null` if the <xref:System.Exception.InnerException%2A> property does not supply the inner exception value to the constructor.  
  
 The following table shows the initial property values for an instance of <xref:System.Reflection.TargetInvocationException>.  
  
|Property|Value|  
|--------------|-----------|  
|<xref:System.Exception.InnerException%2A>|The inner exception reference.|  
|<xref:System.Exception.Message%2A>|The error message string.|  
  
 ]]></format>
        </remarks>
        <threadsafe />
      </Docs>
    </Member>
    <Member MemberName=".ctor">
      <MemberSignature Language="C#" Value="public TargetInvocationException (string message, Exception inner);" />
      <MemberSignature Language="ILAsm" Value=".method public hidebysig specialname rtspecialname instance void .ctor(string message, class System.Exception inner) cil managed" />
      <MemberType>Constructor</MemberType>
      <AssemblyInfo>
        <AssemblyName>mscorlib</AssemblyName>
        <AssemblyVersion>1.0.5000.0</AssemblyVersion>
        <AssemblyVersion>2.0.0.0</AssemblyVersion>
        <AssemblyVersion>4.0.0.0</AssemblyVersion>
      </AssemblyInfo>
      <Parameters>
        <Parameter Name="message" Type="System.String" />
        <Parameter Name="inner" Type="System.Exception" />
      </Parameters>
      <Docs>
        <param name="message">The error message that explains the reason for the exception.</param>
        <param name="inner">The exception that is the cause of the current exception. If the `inner` parameter is not <see langword="null" />, the current exception is raised in a <see langword="catch" /> block that handles the inner exception.</param>
        <summary>Initializes a new instance of the <see cref="T:System.Reflection.TargetInvocationException" /> class with a specified error message and a reference to the inner exception that is the cause of this exception.</summary>
        <remarks>
          <format type="text/markdown"><![CDATA[  
  
## Remarks  
 An exception that is thrown as a direct result of a previous exception should include a reference to the previous exception in the <xref:System.Exception.InnerException%2A> property. The <xref:System.Exception.InnerException%2A> property returns the same value that is passed into the constructor, or `null` if the <xref:System.Exception.InnerException%2A> property does not supply the inner exception value to the constructor.  
  
 The following table shows the initial property values for an instance of <xref:System.Reflection.TargetInvocationException>.  
  
|Property|Value|  
|--------------|-----------|  
|<xref:System.Exception.InnerException%2A>|The inner exception reference.|  
|<xref:System.Exception.Message%2A>|The error message string.|  
  
 ]]></format>
        </remarks>
        <threadsafe />
      </Docs>
    </Member>
  </Members>
</Type>